<?xml version="1.0"?>
<robot xmlns:xacro="http://www.ros.org/wiki/xacro" name="tita">

  <!-- <xacro:include filename="$(find tita_description)/tita/xacro/materials.xacro"/> -->

  <!-- <link name="world"/>
  <link name="base_footprint"/>
  <joint name="world_fixed" type="fixed">
    <origin xyz="0 0 0" rpy="0 0 0" />
    <parent link="world" />
    <child link="base_footprint" />
  </joint>
  <joint name="base_joint" type="fixed">
    <origin xyz="0 0 0" rpy="0 0 0"/>
    <parent link="base_footprint"/>
    <child link="base_link"/>
  </joint> -->
  <link name="base_link">
    <inertial>
      <origin xyz="0.020452 3.5457E-06 0.01871" rpy="0 0 0" />
      <mass value="13.2" />
      <inertia ixx="0.061855" ixy="-2.6029E-05" ixz="0.00081082" iyy="0.036934" iyz="-1.7269E-05" izz="0.071232" />
    </inertial>
    <visual>
      <origin xyz="0 0 0" rpy="0 0 0" />
      <geometry>
        <mesh filename="/home/amg/tita_0309_ws/tita_ws/src/tita_bal_ign/model/meshes/base_link.STL" />
      </geometry>
      <material name="white">
        <color rgba="1.0 1.0 1.0 1.0"/>
      </material>
    </visual>
    <collision>
      <origin xyz="0 0 0.017" rpy="0 0 0" />
      <geometry>
        <box size="0.47 0.3 0.19" />
      </geometry>
    </collision>
  </link>
  
  <link name="LHR_LINK">
    <inertial>
      <origin xyz="0.0016025 5.0253E-05 0.000638" rpy="0 0 0" />
      <mass value="2.064" />
      <inertia ixx="0.0043044" ixy="-1.3538E-07" ixz="8.054E-05" iyy="0.0029982" iyz="-1.5446E-06" izz="0.0022703" />
    </inertial>
    <visual>
      <origin xyz="0 0 0" rpy="0 0 0" />
      <geometry>
        <mesh filename="/home/amg/tita_0309_ws/tita_ws/src/tita_bal_ign/model/meshes/left_leg_1.STL" />
      </geometry>
      <material name="red">
        <color rgba="1.0 0.0 0.0 1.0"/>
      </material>
    </visual>
  </link>
  
  <joint name="LHR_JOINT" type="fixed">
    <origin xyz="0 0.0895 0" rpy="1.5708 0 1.5708" />
    <parent link="base_link" />
    <child link="LHR_LINK" />
    <axis xyz="0 0 1" />
    <limit lower="-0.785398" upper="0.785398" effort="100" velocity="100" />
  </joint>
  <link name="LHP_LINK">
    <inertial>
      <origin xyz="0.021763 0.0019069 -0.027868" rpy="0 0 0" />
      <mass value="3.0984" />
      <inertia ixx="0.0029784" ixy="-9.6332E-05" ixz="7.878E-05" iyy="0.0064836" iyz="4.3691E-06" izz="0.0088353" />
    </inertial>
    <visual>
      <origin xyz="0 0 0" rpy="0 0 0" />
      <geometry>
        <mesh filename="/home/amg/tita_0309_ws/tita_ws/src/tita_bal_ign/model/meshes/left_leg_2.STL" />
      </geometry>
      <material name="red">
        <color rgba="1.0 0.0 0.0 1.0"/>
      </material>
    </visual>
  </link>
  <joint name="LHP_JOINT" type="fixed">
    <!-- <origin xyz="0.1426 0 0" rpy="-1.5708 1.0472 -1.5708" /> -->
    <origin xyz="0.1426 0 0" rpy="-1.5708 0.5054 -1.5708" />
    <parent link="LHR_LINK" />
    <child link="LHP_LINK" />
    <axis xyz="0 0 1" />
    <limit lower="-1.919862" upper="3.490659" effort="100" velocity="100" />
  </joint>
  <link name="LKP_LINK">
    <inertial>
      <origin xyz="0.095348 0.011698 0.001838" rpy="0 0 0" />
      <mass value="0.57244" />
      <inertia ixx="0.00030595" ixy="0.00035537" ixz="-0.00011764" iyy="0.0032009" iyz="1.129E-05" izz="0.0034209" />
    </inertial>
    <visual>
      <origin xyz="0 0 0" rpy="0 0 0" />
      <geometry>
        <mesh filename="/home/amg/tita_0309_ws/tita_ws/src/tita_bal_ign/model/meshes/left_leg_3.STL" />
      </geometry>
      <material name="red">
        <color rgba="1.0 0.0 0.0 1.0"/>
      </material>
    </visual>
    <collision>
      <origin xyz="0.1 0.021 -0.002" rpy="0 0 -0.131" />
      <geometry>
        <box size="0.2 0.07 0.05" />
      </geometry>
    </collision>
  </link>
  <joint name="LKP_JOINT" type="fixed">
    <!-- <origin xyz="0.2 0 0" rpy="0 0 -2.0944" /> -->
    <origin xyz="0.2 0 0" rpy="0 0 -1.0107" />
    <parent link="LHP_LINK" />
    <child link="LKP_LINK" />
    <axis xyz="0 0 1" />
    <limit lower="-2.670354" upper="-0.698132" effort="100" velocity="100" />
    <!-- <limit lower="0.0" upper="2.670354" effort="100" velocity="100" /> -->
  </joint>
  <link name="LW_LINK">
    <inertial>
      <origin xyz="-2.267E-06 -1.6471E-06 -0.00095616" rpy="0 0 0" />
      <mass value="1.5094" />
      <inertia ixx="0.0035466" ixy="6.9816E-06" ixz="-2.3224E-07" iyy="0.0035053" iyz="-1.7712E-08" izz="0.0069049" />
    </inertial>
    <visual>
      <origin xyz="0 0 0" rpy="0 0 0" />
      <geometry>
        <mesh filename="/home/amg/tita_0309_ws/tita_ws/src/tita_bal_ign/model/meshes/left_leg_4.STL" />
      </geometry>
      <material name="black">
        <color rgba="0.0 0.0 0.0 1.0"/>
      </material>
    </visual>
    <collision>
      <origin xyz="0 0 0" rpy="0 0 0" />
      <geometry>
        <cylinder radius="0.0925" length="0.034" />
      </geometry>
    </collision>
  </link>
  <joint name="LW_JOINT" type="revolute">
    <origin xyz="0.2 0 0.0514" rpy="0 0 0" />
    <parent link="LKP_LINK" />
    <child link="LW_LINK" />
    <axis xyz="0 0 1" />
    <limit lower="-6.283185e4" upper="6.283185e4" effort="100" velocity="100" />
  </joint>
  <link name="RHR_LINK">
    <inertial>
      <origin xyz="-0.0016025 5.0253E-05 0.00063801" rpy="0 0 0" />
      <mass value="2.064" />
      <inertia ixx="0.0043044" ixy="1.3538E-07" ixz="-8.054E-05" iyy="0.0029982" iyz="-1.5359E-06" izz="0.0022703" />
    </inertial>
    <visual>
      <origin xyz="0 0 0" rpy="0 0 0" />
      <geometry>
        <mesh filename="/home/amg/tita_0309_ws/tita_ws/src/tita_bal_ign/model/meshes/right_leg_1.STL" />
      </geometry>
      <material name="red">
        <color rgba="1.0 0.0 0.0 1.0"/>
      </material>
    </visual>
  </link>
  <joint name="RHR_JOINT" type="fixed">
    <origin xyz="0 -0.0895 0" rpy="1.5708 0 1.5708" />
    <parent link="base_link" />
    <child link="RHR_LINK" />
    <axis xyz="0 0 1" />
    <limit lower="-0.785398" upper="0.785398" effort="100" velocity="100" />
  </joint>
  <link name="RHP_LINK">
    <inertial>
      <origin xyz="0.021763 0.0019065 0.027873" rpy="0 0 0" />
      <mass value="3.0987" />
      <inertia ixx="0.0029784" ixy="-9.6347E-05" ixz="-7.8776E-05" iyy="0.0064836" iyz="-4.3711E-06" izz="0.0088353" />
    </inertial>
    <visual>
      <origin xyz="0 0 0" rpy="0 0 0" />
      <geometry>
        <mesh filename="/home/amg/tita_0309_ws/tita_ws/src/tita_bal_ign/model/meshes/right_leg_2.STL" />
      </geometry>
      <material name="red">
        <color rgba="1.0 0.0 0.0 1.0"/>
      </material>
    </visual>
  </link>
  <joint name="RHP_JOINT" type="fixed">
    <!-- <origin xyz="-0.1426 0 0" rpy="-1.5708 1.0472 -1.5708" /> -->
    <origin xyz="-0.1426 0 0" rpy="-1.5708 0.5054 -1.5708" />
    <parent link="RHR_LINK" />
    <child link="RHP_LINK" />
    <axis xyz="0 0 1" />
    <limit lower="-1.919862" upper="3.490659" effort="100" velocity="100" />
  </joint>
  <link name="RKP_LINK">
    <inertial>
      <origin xyz="0.095348 0.011698 -0.001838" rpy="0 0 0" />
      <mass value="0.57244" />
      <inertia ixx="0.00030595" ixy="0.00035537" ixz="0.00011764" iyy="0.0032009" iyz="-1.129E-05" izz="0.0034209" />
    </inertial>
    <visual>
      <origin xyz="0 0 0" rpy="0 0 0" />
      <geometry>
        <mesh filename="/home/amg/tita_0309_ws/tita_ws/src/tita_bal_ign/model/meshes/right_leg_3.STL" />
      </geometry>
      <material name="red">
        <color rgba="1.0 0.0 0.0 1.0"/>
      </material>
    </visual>
    <collision>
      <origin xyz="0.1 0.021 -0.002" rpy="0 0 -0.131" />
      <geometry>
        <box size="0.2 0.07 0.05" />
      </geometry>
    </collision>
  </link>
  <joint name="RKP_JOINT" type="fixed">
    <!-- <origin xyz="0.2 0 0" rpy="0 0 -2.0944" /> -->
    <origin xyz="0.2 0 0" rpy="0 0 -1.0107" />
    <parent link="RHP_LINK" />
    <child link="RKP_LINK" />
    <axis xyz="0 0 1" />
    <limit lower="-2.670354" upper="-0.698132" effort="100" velocity="100" />
    <!-- <limit lower="0.0" upper="2.670354" effort="100" velocity="100" /> -->
  </joint>
  <link name="RW_LINK">
    <inertial>
      <origin xyz="-2.3798E-06 -1.5854E-06 0.00095595" rpy="0 0 0" />
      <mass value="1.5094" />
      <inertia ixx="0.0035465" ixy="7.0548E-06" ixz="2.3146E-07" iyy="0.0035052" iyz="1.9287E-08" izz="0.0069047" />
    </inertial>
    <visual>
      <origin xyz="0 0 0" rpy="0 0 0" />
      <geometry>
        <mesh filename="/home/amg/tita_0309_ws/tita_ws/src/tita_bal_ign/model/meshes/right_leg_4.STL" />
      </geometry>
      <material name="black">
        <color rgba="0.0 0.0 0.0 1.0"/>
      </material>
    </visual>
    <collision>
      <origin xyz="0 0 0" rpy="0 0 0" />
      <geometry>
        <cylinder radius="0.0925" length="0.034" />
      </geometry>
    </collision>
  </link>
  <joint name="RW_JOINT" type="revolute">
    <origin xyz="0.2 0 -0.0514" rpy="0 0 0" />
    <parent link="RKP_LINK" />
    <child link="RW_LINK" />
    <axis xyz="0 0 1" />
    <limit lower="-6.283185e4" upper="6.283185e4" effort="100" velocity="100" />
  </joint>
  <joint name="imu_joint" type="fixed">
    <parent link="base_link"/>
    <child link="imu_link"/>
    <origin rpy="0 0 0" xyz="0 0 0"/>
  </joint>
  <link name="imu_link">
    <inertial>
      <mass value="0.001"/>
      <origin rpy="0 0 0" xyz="0 0 0"/>
      <inertia ixx="0.0001" ixy="0" ixz="0" iyy="0.0001" iyz="0" izz="0.0001"/>
    </inertial>
    <visual>
      <origin rpy="0 0 0" xyz="0 0 0"/>
      <geometry>
        <box size="0.001 0.001 0.001"/>
      </geometry>
      <material name="red"/>
    </visual>
    <collision>
      <origin rpy="0 0 0" xyz="0 0 0"/>
      <geometry>
        <box size=".001 .001 .001"/>
      </geometry>
    </collision>
  </link>

  <gazebo reference="imu_link">
    <gravity>true</gravity>
    <sensor name="imu_sensor" type="imu">
      <always_on>true</always_on>
      <update_rate>1000</update_rate>
    </sensor>
  </gazebo>

  <!-- </gazebo>
  <gazebo reference="base">
    <gravity>true</gravity>
  </gazebo> -->
  <gazebo reference="base_link">
    <self_collide>false</self_collide>
    <gravity>true</gravity>
  </gazebo>
  <gazebo reference="LHR_LINK">
    <self_collide>false</self_collide>
    <gravity>true</gravity>
  </gazebo>
  <gazebo reference="LHP_LINK">
    <self_collide>false</self_collide>
    <gravity>true</gravity>
  </gazebo>
  <gazebo reference="LKP_LINK">
    <self_collide>false</self_collide>
    <gravity>true</gravity>
  </gazebo>
  <gazebo reference="LW_LINK">
    <self_collide>false</self_collide>
    <gravity>true</gravity>
  </gazebo>
  <gazebo reference="RHR_LINK">
    <self_collide>false</self_collide>
    <gravity>true</gravity>
  </gazebo>
  <gazebo reference="RHP_LINK">
    <self_collide>false</self_collide>
    <gravity>true</gravity>
  </gazebo>
  <gazebo reference="RKP_LINK">
    <self_collide>false</self_collide>
    <gravity>true</gravity>
  </gazebo>
  <gazebo reference="RW_LINK">
    <self_collide>false</self_collide>
    <gravity>true</gravity>
  </gazebo>

  <ros2_control name="GazeboSystem" type="system">
    <hardware>
      <plugin>gz_ros2_control/GazeboSimSystem</plugin>
    </hardware>

    <joint name="LHR_JOINT">
      <command_interface name="position">
        <param name="min">-100.0</param>
        <param name="max">100.0</param>
      </command_interface>
      <state_interface name="effort"/>
      <state_interface name="velocity"/>
      <state_interface name="position">
        <param name="initial_value">0.0</param>
      </state_interface>
    </joint>
     <joint name="RHR_JOINT">
      <command_interface name="position">
        <param name="min">-100.0</param>
        <param name="max">100.0</param>
      </command_interface>
      <state_interface name="effort"/>
      <state_interface name="velocity"/>
      <state_interface name="position">
        <param name="initial_value">0.0</param>
      </state_interface>
    </joint>

    <joint name="LHP_JOINT">
      <command_interface name="position">
        <param name="min">-100.0</param>
        <param name="max">100.0</param>
      </command_interface>
      <state_interface name="effort"/>
      <state_interface name="velocity"/>
      <state_interface name="position">
        <param name="initial_value">0.0</param>
      </state_interface>
    </joint>
    <joint name="RHP_JOINT">
      <command_interface name="position">
        <param name="min">-100.0</param>
        <param name="max">100.0</param>
      </command_interface>
      <state_interface name="effort"/>
      <state_interface name="velocity"/>
      <state_interface name="position">
        <param name="initial_value">0.0</param>
      </state_interface>
    </joint>

    <joint name="LKP_JOINT">
      <command_interface name="position">
        <param name="min">-100.0</param>
        <param name="max">100.0</param>
      </command_interface>
      <state_interface name="effort"/>
      <state_interface name="velocity"/>
      <state_interface name="position">
        <param name="initial_value">0.0</param>
      </state_interface>
    </joint>
     <joint name="RKP_JOINT">
      <command_interface name="position">
        <param name="min">-100.0</param>
        <param name="max">100.0</param>
      </command_interface>
      <state_interface name="effort"/>
      <state_interface name="velocity"/>
      <state_interface name="position">
        <param name="initial_value">0.0</param>
      </state_interface>
    </joint>

    <joint name="LW_JOINT">
      <command_interface name="effort">
        <param name="min">-100.0</param>
        <param name="max">100.0</param>
      </command_interface>
      <command_interface name="kp"/>
      <command_interface name="kd"/>

      <state_interface name="velocity"/>
      <state_interface name="position">
        <param name="initial_value">0.0</param>
      </state_interface>
      <state_interface name="effort"/>
    </joint>
    <joint name="RW_JOINT">
      <command_interface name="effort">
        <param name="min">-100.0</param>
        <param name="max">100.0</param>
      </command_interface>
      <command_interface name="kp"/>
      <command_interface name="kd"/>

      <state_interface name="velocity"/>
      <state_interface name="position">
        <param name="initial_value">0.0</param>
      </state_interface>
      <state_interface name="effort"/>
    </joint>

    <sensor name="imu_sensor">
      <state_interface name="orientation.x"/>
      <state_interface name="orientation.y"/>
      <state_interface name="orientation.z"/>
      <state_interface name="orientation.w"/>
      <state_interface name="angular_velocity.x"/>
      <state_interface name="angular_velocity.y"/>
      <state_interface name="angular_velocity.z"/>
      <state_interface name="linear_acceleration.x"/>
      <state_interface name="linear_acceleration.y"/>
      <state_interface name="linear_acceleration.z"/>
    </sensor>

  </ros2_control>

  <!--ROS2 Control-->
  <gazebo>
    <plugin filename="gz_ros2_control-system" name="gz_ros2_control::GazeboSimROS2ControlPlugin">
    <parameters>/home/amg/tita_0309_ws/tita_ws/src/tita_bal_ign/config/tita_controller_pos_2.yaml</parameters>
    </plugin>
    <plugin
      filename="ignition-gazebo-imu-system"
      name="ignition::gazebo::systems::Imu">
    </plugin>
  </gazebo>

  <!-- <gazebo reference="base_link">
    <plugin name="static_base" filename="libgazebo_ros_static_joint.so">
      <bodyName>base_link</bodyName>
    </plugin>
  </gazebo> -->

  <!-- <gazebo>
    <static>true</static>
  </gazebo> -->


  <!-- <gazebo reference="LHR_LINK">
    <joint name="LHP_JOINT">
      <angle>0.5236</angle> 
    </joint>
  </gazebo> -->

</robot>